<mujoco>
  <compiler texturedir="asset"/>
  
  <asset>
    <texture name="texaruco" type="2d" file="5x5_1000-1.png"/>
    <material name="mataruco" texture="texaruco"/>
  </asset>

  <visual>
    <quality offsamples="0"/>
  </visual>
  
  <option gravity = "0 0 -9.81" />
   <worldbody>
      <light diffuse="1 1 1" pos="0 0 20" dir="0 0 -1"/>
			<geom type="plane" size="10 10 0.1" rgba=".9 0 0 1"/>
      <body name="robot" pos="0 0 0.5" euler="0 0 0">
        <joint name="robot_joint" type="hinge" axis = "0 0 1" pos = "0 0 -0.5"/>
				<geom type="box" size=".5 .5 .5" rgba="1 1 1 1" mass="10"/>
        <camera name="robot_camera" pos="0.5 0 0" euler="0 -90 270"/>
        <!-- <camera name="robot_camera" pos="0.5 0 0" fovy="112.35" resolution="928 800" euler="0 -90 270"/> -->
        
        <!-- From depthCamera.dae https://github.com/unitreerobotics/unitree_ros/blob/6a7a9609cebd853062f2182f97dcfbdb711cd61a/robots/go1_description/meshes/depthCamera.dae#L56 -->
        <!-- <xfov sid="xfov">39.59775</xfov>
        <aspect_ratio>1.777778</aspect_ratio>
        <znear sid="znear">0.1</znear>
        <zfar sid="zfar">100</zfar> -->

        <!-- From go1.urdf https://github.com/unitreerobotics/unitree_ros/blob/6a7a9609cebd853062f2182f97dcfbdb711cd61a/robots/go1_description/urdf/go1.urdf#L1348C22-L1348C33 --> 
        <!-- <gazebo reference="camera_face">
          <sensor name="camera_face_camera" type="depth">
            <update_rate>16</update_rate>
            <camera>
              <horizontal_fov>2.094</horizontal_fov> = ~120 degrees
              <image>
                <width>928</width>
                <height>800</height>
                <format>R8G8B8</format>
              </image>
              <clip>
                <near>0.1</near>
                <far>5</far>
              </clip>
            </camera>
            <plugin filename="libgazebo_ros_openni_kinect.so" name="camera_face_controller">
              <baseline>0.025</baseline>
              <alwaysOn>true</alwaysOn>
              <updateRate>0.0</updateRate>
              <cameraName>camera_face_ir</cameraName>
              <imageTopicName>/camera_face/color/image_raw</imageTopicName>
              <cameraInfoTopicName>/camera_face/color/camera_info</cameraInfoTopicName>
              <depthImageTopicName>/camera_face/depth/image_raw</depthImageTopicName>
              <depthImageInfoTopicName>/camera_face/depth/camera_info</depthImageInfoTopicName>
              <pointCloudTopicName>/cam1/point_cloud_face</pointCloudTopicName>
              <frameName>camera_optical_face</frameName>
              <pointCloudCutoff>0.1</pointCloudCutoff>
              <pointCloudCutoffMax>1.5</pointCloudCutoffMax>
              <distortionK1>0.0</distortionK1>
              <distortionK2>0.0</distortionK2>
              <distortionK3>0.0</distortionK3>
              <distortionT1>0.0</distortionT1>
              <distortionT2>0.0</distortionT2>
              <CxPrime>0</CxPrime>
              <Cx>0.0045</Cx>
              <Cy>0.0039</Cy>
              <focalLength>0</focalLength>
              <hackBaseline>0</hackBaseline>
            </plugin>
          </sensor>
        </gazebo> -->

      </body>
      <body name='obstacle1' pos="3 0 0.5" euler="0 0 0">
				<joint name='joint1' type='slide' axis='0 1 0' pos = '0 0 0'/>
				<geom type="box" size=".5 .5 .5" material="mataruco" euler="0 90 0" rgba="1 1 1 1" mass="10"/>
        <camera name="obstacle_camera1" pos="0 0 1" zaxis="0 0 1"/>
        <!-- <body name="size_check" pos="-0.5 0.2975 0">
          <geom type="box" size="0.1 0.01 0.2875" rgba="0.9 0 0 1"/>
        </body> -->
      </body>
      <body name='obstacle2' pos="0 3 0.5" euler="0 0 0">
				<joint name='joint2' type='slide' axis='1 0 0' pos = '0 0 0'/>
				<geom type="box" size=".5 .5 .5" rgba="1 0 0 1" mass="10"/>
        <camera name="obstacle_camera2" pos="0 0 1" zaxis="0 0 1"/>
      </body>
      <body name='obstacle3' pos="-3 0 0.5" euler="0 0 0">
				<joint name='joint3' type='slide' axis='1 0 0' pos = '0 0 0'/>
				<geom type="box" size=".5 .5 .5" rgba="0 1 0 1" mass="10"/>
        <camera name="obstacle_camera3" pos="0 0 1" zaxis="0 0 1"/>
      </body>
      <body name='obstacle4' pos="0 -3 0.5" euler="0 0 0">
				<joint name='joint4' type='slide' axis='1 0 0' pos = '0 0 0'/>
				<geom type="box" size=".5 .5 .5" rgba="0 0 1 1" mass="10"/>
        <camera name="obstacle_camera4" pos="0 0 1" zaxis="0 0 1"/>
      </body>
    </worldbody>
    
    <actuator>
      <motor name="force" joint="robot_joint"  gear="1" />
    </actuator>
</mujoco>
