<?xml version="1.0" ?>
<mujoco model="objects">
  <include file="objects_benchmark.xml" />
  <asset>
    <material name='plane' reflectance='0' texrepeat='1 1' texture='plane' texuniform='true'/>
    <texture builtin='checker' height='512' name='plane' rgb1='0.2 0.2 0.2' rgb2='0.4 0.4 0.4' type='2d' width='512'/>
    <texture builtin='gradient' height='128' rgb1='0.6 0.8 1' rgb2='0 0 0' type='skybox' width='128'/>
    <!--texture type="skybox" builtin="gradient" rgb1="1.0 1.0 1.0" rgb2="1.0 1.0 1.0" width="512" height="512"/-->
      <!--texture name="plane" type="2d" builtin="flat" rgb1="1 1 1" rgb2="1 1 1" width="512" height="512" mark="cross" markrgb="0 0 0"/-->
      <!--material name="plane" reflectance="0.0" texture="plane" texrepeat="3 3" texuniform="true"/-->
  </asset>

  <visual>
      <rgba com="0.502 1.0 0 0.5" contactforce="0.98 0.4 0.4 0.7" contactpoint="1.0 1.0 0.6 0.4"/>
      <scale com="0.2" forcewidth="0.035" contactwidth="0.10" contactheight="0.04"/>
      <global offwidth="640" offheight="480"/>
  </visual>

  <default>
    <!-- <geom contype="1" conaffinity="1" friction="0.6 0.3 0.3" rgba="0.5 0.6 0.7 1" margin="0.001" group="0"/> -->
    <geom contype="1" conaffinity="1" friction="0.6 0.3 0.3" rgba="0.5 0.6 0.7 1" margin="0.001" group="0"/>

    <light castshadow="false" diffuse="1 1 1"/>
    <camera fovy="60"/>
    <joint damping="0.01" armature="0.01" frictionloss="0.2" />
  </default>

  <worldbody>
    <light directional="true" diffuse=".8 .8 .8" pos="0 0 10" dir="0 0 -10"/>
    <geom name='floor' type='plane' conaffinity='1' condim='3' contype='1' rgba="0.5 0.9 0.9 0.1" material='plane' pos='0 0 0' size='0 0 1'/>
    <body pos="0 0 0.25" euler="0 0 0">
        <joint name="robot" pos = "0 0 -0.5"/>
        <geom type="box" size=".25 .25 .25" rgba="1 1 1 1" mass="10"/>
        <camera name="robot_camera" pos="0.25 0 0.25" euler="0 -90 270"/>
      </body>
  </worldbody>
</mujoco>
